<?xml version="1.0" encoding="utf-8"?>
<!-- This URDF was automatically created by SolidWorks to URDF Exporter! Originally created by Stephen Brawner (brawner@gmail.com) 
     Commit Version: 1.6.0-1-g15f4949  Build Version: 1.6.7594.29634
     For more information, please see http://wiki.ros.org/sw_urdf_exporter -->
<robot
  name="urdf_remade">
 
 	<link name="world" />

  <joint name="fixed_base" type="fixed">
        <parent link="world" />
        <child link="base_link" />
    </joint>
  
  <link
    name="base_link">
    <inertial>
      <origin
        xyz="-0.00036123 -0.00042605 0.022628"
        rpy="0 0 0" />
      <mass
        value="0.18873" />
      <inertia
        ixx="0.00025902"
        ixy="0"
        ixz="0"
        iyy="0.00025783"
        iyz="0"
        izz="0.00039006" />
    </inertial>
    <visual>
      <origin
        xyz="0 0 0"
        rpy="0 0 0" />
      <geometry>
        <mesh
          filename="package://manipulator_description/meshes/base_link.STL" />
      </geometry>
      <material
        name="">
        <color
          rgba="0.098039 0.098039 0.098039 1"  />
      </material>
    </visual>
    <collision>
      <origin
        xyz="0 0 0"
        rpy="0 0 0" />
      <geometry>
        <mesh
          filename="package://manipulator_description/meshes/base_link.STL" />
      </geometry>
    </collision>
  </link>
  
  <link
    name="mancal_link">
    <inertial>
      <origin
        xyz="-0.010397 -0.00033628 0.012328"
        rpy="0 0 0" />
      <mass
        value="0.0822" />
      <inertia
        ixx="7.3019E-05"
        ixy="0"
        ixz="1.106E-05"
        iyy="6.8027E-05"
        iyz="0"
        izz="7.0545E-05" />
    </inertial>
    <visual>
      <origin
        xyz="0 0 0"
        rpy="0 0 0" />
      <geometry>
        <mesh
          filename="package://manipulator_description/meshes/mancal_link.STL" />
      </geometry>
      <material
        name="">
        <color
          rgba="0.098039 0.098039 0.098039 1"  />
      </material>
    </visual>
    <collision>
      <origin
        xyz="0 0 0"
        rpy="0 0 0" />
      <geometry>
        <mesh
          filename="package://manipulator_description/meshes/mancal_link.STL" />
      </geometry>
    </collision>
  </link>
  <joint
    name="joint_base_mancal"
    type="revolute">
    <origin
      xyz="-0.0030392 -0.00072042 0.065"
      rpy="0 0 -3.1273" />
    <parent
      link="base_link" />
    <child
      link="mancal_link" />
    <axis
      xyz="0 0 -1" />
    <limit
      lower="0"
      upper="3.14"
      effort="200"
      velocity="2" />
  </joint>
  
  <link
    name="camera">
    <visual>
      <geometry>
        <box size= "0.012 0.012 0.012" />
      </geometry>
      <material
        name="">
        <color
          rgba="1.0 0.098039 0.098039 1" />
      </material>
    </visual>
  </link> 
  
  <joint name="fixed_camera" type="fixed">
      <origin
      xyz="0.03 -0.03 0.071"
      rpy="-1.57 0 0" />
      <parent link="base_link" />
      <child link="camera" />
    </joint>
  
  <link
    name="link_1">
    <inertial>
      <origin
        xyz="-0.007213 -0.0035323 0.035814"
        rpy="0 0 0" />
      <mass
        value="0.088001" />
      <inertia
        ixx="0.00010734"
        ixy="0"
        ixz="0"
        iyy="9.8432E-05"
        iyz="0"
        izz="2.2487E-05" />
    </inertial>
    <visual>
      <origin
        xyz="0 0 0"
        rpy="0 0 0" />
      <geometry>
        <mesh
          filename="package://manipulator_description/meshes/link_1.STL" />
      </geometry>
      <material
        name="">
        <color
          rgba="0.098039 0.098039 0.098039 1"  />
      </material>
    </visual>
    <collision>
      <origin
        xyz="0 0 0"
        rpy="0 0 0" />
      <geometry>
        <mesh
          filename="package://manipulator_description/meshes/link_1.STL" />
      </geometry>
    </collision>
  </link>
  <joint
    name="joint_mancal_link1"
    type="revolute">
    <origin
      xyz="-0.0036813 -0.00011907 0.0398"
      rpy="1.5708 0 3.1416" />
    <parent
      link="mancal_link" />
    <child
      link="link_1" />
    <axis
      xyz="-0.99948 0 0.032327" />
    <limit
      lower="-0.08"
      upper="2.8"
      effort="200"
      velocity="2" />
  </joint>
  <link
    name="link_2">
    <inertial>
      <origin
        xyz="0.0018709 -0.0062333 0.030663"
        rpy="0 0 0" />
      <mass
        value="0.063942" />
      <inertia
        ixx="7.284E-05"
        ixy="0"
        ixz="0"
        iyy="6.3073E-05"
        iyz="0"
        izz="1.6517E-05" />
    </inertial>
    <visual>
      <origin
        xyz="0 0 0"
        rpy="0 0 0" />
      <geometry>
        <mesh
          filename="package://manipulator_description/meshes/link_2.STL" />
      </geometry>
      <material
        name="">
        <color
          rgba="0.098039 0.098039 0.098039 1"  />
      </material>
    </visual>
    <collision>
      <origin
        xyz="0 0 0"
        rpy="0 0 0" />
      <geometry>
        <mesh
          filename="package://manipulator_description/meshes/link_2.STL" />
      </geometry>
    </collision>
  </link>
  <joint
    name="joint_link1_link2"
    type="revolute">
    <origin
      xyz="0.019243 -0.006808 0.069082"
      rpy="0 0 0" />
    <parent
      link="link_1" />
    <child
      link="link_2" />
    <axis
      xyz="0.99948 0 -0.032327" />
    <limit
      lower="-1.39"
      upper="1.39"
      effort="200"
      velocity="2" />
  </joint>
  <link
    name="link_3">
    <inertial>
      <origin
        xyz="-0.0066835 -0.042699 0.044103"
        rpy="0 0 0" />
      <mass
        value="0.054134" />
      <inertia
        ixx="3.9068E-05"
        ixy="0"
        ixz="0"
        iyy="2.1688E-05"
        iyz="1.6276E-05"
        izz="2.6129E-05" />
    </inertial>
    <visual>
      <origin
        xyz="0 0 0"
        rpy="0 0 0" />
      <geometry>
        <mesh
          filename="package://manipulator_description/meshes/link_3.STL" />
      </geometry>
      <material
        name="">
        <color
          rgba="0.098039 0.098039 0.098039 1"  />
      </material>
    </visual>
    <collision>
      <origin
        xyz="0 0 0"
        rpy="0 0 0" />
      <geometry>
        <mesh
          filename="package://manipulator_description/meshes/link_3.STL" />
      </geometry>
    </collision>
  </link>
  <joint
    name="joint_link2_link3"
    type="revolute">
    <origin
      xyz="-0.013691 -0.011936 0.059274"
      rpy="0 0 0" />
    <parent
      link="link_2" />
    <child
      link="link_3" />
    <axis
      xyz="-0.99948 0 0.032327" />
    <limit
      lower="-1.57"
      upper="1.57"
      effort="200"
      velocity="2" />
  </joint>
  <link
    name="gripper">
    <inertial>
      <origin
        xyz="0.01442 -0.0023726 0.0063946"
        rpy="0 0 0" />
      <mass
        value="0.054134" />
      <inertia
        ixx="3.9068E-05"
        ixy="0"
        ixz="0"
        iyy="2.1688E-05"
        iyz="-1.6276E-05"
        izz="2.6129E-05" />
    </inertial>
    <visual>
      <origin
        xyz="0 0 0"
        rpy="0 0 0" />
      <geometry>
        <mesh
          filename="package://manipulator_description/meshes/gripper.STL" />
      </geometry>
      <material
        name="">
        <color
          rgba="0.098039 0.098039 0.098039 1"  />
      </material>
    </visual>
    <collision>
      <origin
        xyz="0 0 0"
        rpy="0 0 0" />
      <geometry>
        <mesh
          filename="package://manipulator_description/meshes/gripper.STL" />
      </geometry>
    </collision>
  </link> 

   <joint
    name="joint_link3_gripper"
    type="fixed">
    <origin
      xyz="0.0077365 -0.040327 0.050497"
      rpy="3.1416 0 3.1416" />
    <parent
      link="link_3" />
    <child
      link="gripper" />
    <axis
      xyz="0.019686 -0.79321 0.60863" />
    <limit
      lower="-0.35"
      upper="0.35"
      effort="200"
      velocity="2" />
  </joint>
   

  <link name="ee_center" />

   <joint
    name="joint_gripper_ee_center"
    type="fixed">
    <origin xyz="-0.01 -0.09 0.095" rpy="0.74 0 0" />
    <parent link="link_3" />
    <child link="ee_center" />
  </joint>


</robot>