<?xml version="1.0" encoding="utf-8"?>
<!-- This URDF was automatically created by SolidWorks to URDF Exporter! Originally created by Stephen Brawner (brawner@gmail.com) 
     Commit Version: 1.6.0-1-g15f4949  Build Version: 1.6.7594.29634
     For more information, please see http://wiki.ros.org/sw_urdf_exporter -->
<robot
  name="urdf_remade">
  
  <link name="world" />

  <joint name="fixed_base" type="fixed">
        <parent link="world" />
        <child link="base_link" />
    </joint>

  <link
    name="base_link">
    <inertial>
      <origin
        xyz="-0.00036123 -0.00042605 0.022628"
        rpy="0 0 0" />
      <mass
        value="0.18873" />
      <inertia
        ixx="0.00025902"
        ixy="0.00017171"
        ixz="-0.00013068"
        iyy="0.00025783"
        iyz="0.00087758"
        izz="0.00039006" />
    </inertial>
    <visual>
      <origin
        xyz="0 0 0"
        rpy="0 0 0" />
      <geometry>
        <mesh
          filename="package://manipulator_description/meshes/base_link.STL" />
      </geometry>
      <material
        name="">
        <color
          rgba="0.098039 0.098039 0.098039 1" />
      </material>
    </visual>
    <collision>
      <origin
        xyz="0 0 0"
        rpy="0 0 0" />
      <geometry>
        <mesh
          filename="package://manipulator_description/meshes/base_link.STL" />
      </geometry>
    </collision>
  </link>
  <link
    name="mancal_link">
    <inertial>
      <origin
        xyz="0.0082382 -0.0063516 0.012328"
        rpy="0 0 0" />
      <mass
        value="0.0822" />
      <inertia
        ixx="0.00071159"
        ixy="-0.00024189"
        ixz="-0.00087636"
        iyy="0.00069887"
        iyz="0.00067566"
        izz="0.00070545" />
    </inertial>
    <visual>
      <origin
        xyz="0 0 0"
        rpy="0 0 0" />
      <geometry>
        <mesh
          filename="package://manipulator_description/meshes/mancal_link.STL" />
      </geometry>
      <material
        name="">
        <color
          rgba="0.098039 0.098039 0.098039 1" />
      </material>
    </visual>
    <collision>
      <origin
        xyz="0 0 0"
        rpy="0 0 0" />
      <geometry>
        <mesh
          filename="package://manipulator_description/meshes/mancal_link.STL" />
      </geometry>
    </collision>
  </link>
  <joint
    name="joint_base_mancal"
    type="revolute">
    <origin
      xyz="0.0017893 -0.0022034 0.065"
      rpy="0 0 -3.1273" />
    <parent
      link="base_link" />
    <child
      link="mancal_link" />
    <axis
      xyz="0 0 -1" />
    <limit
      lower="0"
      upper="3.14"
      effort="200"
      velocity="2" />
  </joint>
  <link
    name="link_1">
    <inertial>
      <origin
        xyz="-0.12225 0.002316 0.023263"
        rpy="0 0 0" />
      <mass
        value="0.37066" />
      <inertia
        ixx="0.00017655"
        ixy="0.00014663"
        ixz="0.00036049"
        iyy="0.0021231"
        iyz="-0.00027903"
        izz="0.0020023" />
    </inertial>
    <visual>
      <origin
        xyz="0 0 0"
        rpy="0 0 0" />
      <geometry>
        <mesh
          filename="package://manipulator_description/meshes/link_1.STL" />
      </geometry>
      <material
        name="">
        <color
          rgba="0.098039 0.098039 0.098039 1" />
      </material>
    </visual>
    <collision>
      <origin
        xyz="0 0 0"
        rpy="0 0 0" />
      <geometry>
        <mesh
          filename="package://manipulator_description/meshes/link_1.STL" />
      </geometry>
    </collision>
  </link>
  <joint
    name="joint_mancal_link1"
    type="revolute">
    <origin
      xyz="-0.0018347 0.0014146 0.0398"
      rpy="0 0 0.914" />
    <parent
      link="mancal_link" />
    <child
      link="link_1" />
    <axis
      xyz="0 1 0" />
    <limit
      lower="-0.08"
      upper="2.8"
      effort="200"
      velocity="2" />
  </joint>
  <link
    name="link_2">
    <inertial>
      <origin
        xyz="-0.078673 -0.023987 0.014926"
        rpy="0 0 0" />
      <mass
        value="0.20121" />
      <inertia
        ixx="7.6875E-05"
        ixy="-0.00018666"
        ixz="0.00097421"
        iyy="0.00062739"
        iyz="0.00035413"
        izz="0.0005719" />
    </inertial>
    <visual>
      <origin
        xyz="0 0 0"
        rpy="0 0 0" />
      <geometry>
        <mesh
          filename="package://manipulator_description/meshes/link_2.STL" />
      </geometry>
      <material
        name="">
        <color
          rgba="0.098039 0.098039 0.098039 1" />
      </material>
    </visual>
    <collision>
      <origin
        xyz="0 0 0"
        rpy="0 0 0" />
      <geometry>
        <mesh
          filename="package://manipulator_description/meshes/link_2.STL" />
      </geometry>
    </collision>
  </link>
  <joint
    name="joint_link1_link2"
    type="revolute">
    <origin
      xyz="-0.24449 0 0.046524"
      rpy="0 0 0" />
    <parent
      link="link_1" />
    <child
      link="link_2" />
    <axis
      xyz="0 1 0" />
    <limit
      lower="-1.39"
      upper="1.39"
      effort="200"
      velocity="2" />
  </joint>
  <link
    name="link_3">
    <inertial>
      <origin
        xyz="-0.043002 -0.0092993 0.012483"
        rpy="0 0 0" />
      <mass
        value="0.1114" />
      <inertia
        ixx="4.6736E-05"
        ixy="-0.00031676"
        ixz="0.00024917"
        iyy="0.00013144"
        iyz="0.00010543"
        izz="0.00010147" />
    </inertial>
    <visual>
      <origin
        xyz="0 0 0"
        rpy="0 0 0" />
      <geometry>
        <mesh
          filename="package://manipulator_description/meshes/link_3.STL" />
      </geometry>
      <material
        name="">
        <color
          rgba="0.098039 0.098039 0.098039 1" />
      </material>
    </visual>
    <collision>
      <origin
        xyz="0 0 0"
        rpy="0 0 0" />
      <geometry>
        <mesh
          filename="package://manipulator_description/meshes/link_3.STL" />
      </geometry>
    </collision>
  </link>
  <joint
    name="joint_link2_link3"
    type="revolute">
    <origin
      xyz="-0.15734 0.013 0.02985"
      rpy="0 0 0" />
    <parent
      link="link_2" />
    <child
      link="link_3" />
    <axis
      xyz="0 -1 0" />
    <limit
      lower="-1.57"
      upper="1.57"
      effort="200"
      velocity="2" />
  </joint>
  <link
    name="gripper">
    <inertial>
      <origin
        xyz="-0.020033 0.0039871 0.010471"
        rpy="0 0 0" />
      <mass
        value="0.014246" />
      <inertia
        ixx="0.00045598"
        ixy="0.00068889"
        ixz="0.00035533"
        iyy="0.00088054"
        iyz="-0.00094032"
        izz="0.00050149" />
    </inertial>
    <visual>
      <origin
        xyz="0 0 0"
        rpy="0 0 0" />
      <geometry>
        <mesh
          filename="package://manipulator_description/meshes/gripper.STL" />
      </geometry>
      <material
        name="">
        <color
          rgba="0.098039 0.098039 0.098039 1" />
      </material>
    </visual>
    <collision>
      <origin
        xyz="0 0 0"
        rpy="0 0 0" />
      <geometry>
        <mesh
          filename="package://manipulator_description/meshes/gripper.STL" />
      </geometry>
    </collision>
  </link>
  <joint
    name="joint_link3_gripper"
    type="revolute">
    <origin
      xyz="-0.079874 -0.010002 0.014725"
      rpy="1.5708 0 -0.914" />
    <parent
      link="link_3" />
    <child
      link="gripper" />
    <axis
      xyz="0.17293 0.95905 -0.2243" />
    <limit
      lower="-0.35"
      upper="0.35"
      effort="200"
      velocity="2" />
  </joint>

  <link name="ee_center" />

   <joint
    name="joint_gripper_ee_center"
    type="fixed">
    <origin xyz="-0.06 0 0.03" rpy="0 0 0" />
    <parent link="gripper" />
    <child link="ee_center" />
  </joint>
</robot>